<?xml version="1.0" encoding="UTF-8"?>
<testng-results skipped="0" failed="1" total="1" passed="0">
  <reporter-output>
  </reporter-output>
  <suite name="Default suite" duration-ms="35436" started-at="2018-09-20T07:02:16Z" finished-at="2018-09-20T07:02:52Z">
    <groups>
    </groups>
    <test name="Default test" duration-ms="35436" started-at="2018-09-20T07:02:16Z" finished-at="2018-09-20T07:02:52Z">
      <class name="demo.Datadriven">
        <test-method status="PASS" signature="beforeTest()[pri:0, instance:demo.Datadriven@36d4b5c]" name="beforeTest" is-config="true" duration-ms="10634" started-at="2018-09-20T12:32:16Z" finished-at="2018-09-20T12:32:27Z">
          <reporter-output>
          </reporter-output>
        </test-method> <!-- beforeTest -->
        <test-method status="FAIL" signature="TestMercury()[pri:0, instance:demo.Datadriven@36d4b5c]" name="TestMercury" duration-ms="24482" started-at="2018-09-20T12:32:27Z" finished-at="2018-09-20T12:32:51Z">
          <exception class="java.lang.AssertionError">
            <message>
              <![CDATA[expected [Sign-on: Mercury Tours] but found [Find a Flight: Mercury Tours:]]]>
            </message>
            <full-stacktrace>
              <![CDATA[java.lang.AssertionError: expected [Sign-on: Mercury Tours] but found [Find a Flight: Mercury Tours:]
	at org.testng.Assert.fail(Assert.java:89)
	at org.testng.Assert.failNotEquals(Assert.java:489)
	at org.testng.Assert.assertEquals(Assert.java:118)
	at org.testng.Assert.assertEquals(Assert.java:171)
	at org.testng.Assert.assertEquals(Assert.java:181)
	at demo.Datadriven.login(Datadriven.java:56)
	at demo.Datadriven.Readexcel(Datadriven.java:38)
	at demo.Datadriven.TestMercury(Datadriven.java:27)
	at sun.reflect.NativeMethodAccessorImpl.invoke0(Native Method)
	at sun.reflect.NativeMethodAccessorImpl.invoke(Unknown Source)
	at sun.reflect.DelegatingMethodAccessorImpl.invoke(Unknown Source)
	at java.lang.reflect.Method.invoke(Unknown Source)
	at org.testng.internal.MethodInvocationHelper.invokeMethod(MethodInvocationHelper.java:80)
	at org.testng.internal.Invoker.invokeMethod(Invoker.java:715)
	at org.testng.internal.Invoker.invokeTestMethod(Invoker.java:907)
	at org.testng.internal.Invoker.invokeTestMethods(Invoker.java:1237)
	at org.testng.internal.TestMethodWorker.invokeTestMethods(TestMethodWorker.java:127)
	at org.testng.internal.TestMethodWorker.run(TestMethodWorker.java:111)
	at org.testng.TestRunner.privateRun(TestRunner.java:767)
	at org.testng.TestRunner.run(TestRunner.java:617)
	at org.testng.SuiteRunner.runTest(SuiteRunner.java:334)
	at org.testng.SuiteRunner.runSequentially(SuiteRunner.java:329)
	at org.testng.SuiteRunner.privateRun(SuiteRunner.java:291)
	at org.testng.SuiteRunner.run(SuiteRunner.java:240)
	at org.testng.SuiteRunnerWorker.runSuite(SuiteRunnerWorker.java:51)
	at org.testng.SuiteRunnerWorker.run(SuiteRunnerWorker.java:85)
	at org.testng.TestNG.runSuitesSequentially(TestNG.java:1197)
	at org.testng.TestNG.runSuitesLocally(TestNG.java:1122)
	at org.testng.TestNG.run(TestNG.java:1030)
	at org.testng.remote.AbstractRemoteTestNG.run(AbstractRemoteTestNG.java:114)
	at org.testng.remote.RemoteTestNG.initAndRun(RemoteTestNG.java:251)
	at org.testng.remote.RemoteTestNG.main(RemoteTestNG.java:77)
]]>
            </full-stacktrace>
          </exception> <!-- java.lang.AssertionError -->
          <reporter-output>
          </reporter-output>
        </test-method> <!-- TestMercury -->
        <test-method status="PASS" signature="afterTest()[pri:0, instance:demo.Datadriven@36d4b5c]" name="afterTest" is-config="true" duration-ms="269" started-at="2018-09-20T12:32:51Z" finished-at="2018-09-20T12:32:52Z">
          <reporter-output>
          </reporter-output>
        </test-method> <!-- afterTest -->
      </class> <!-- demo.Datadriven -->
    </test> <!-- Default test -->
  </suite> <!-- Default suite -->
</testng-results>
